<!DOCTYPE html>
<html lang="pt-br">

<head>
    <meta charset="UTF-8">
    <meta name="viewport" content="width=device-width, initial-scale=1.0">
    <title>Promisses</title>
</head>

<body>
    <script>
         function somar(n1, n2) {
                return new Promise((resolve, reject) => {
                    setTimeout(() => {
                        const resultado = n1 + n2;

                        if (resultado % 2 !== 0) {
                            reject(new Error("O valor é ímpar"));
                        } else {
                            resolve(resultado);
                        }
                    }, 2000);
                })
            }

            somar(1, 2)
                .then(resultado => console.log(`A operação foi bem sucedida! O número ${resultado} é par`))
                .catch(error => console.log(`A operação falhou! ${error.message}`));
            
            (async () => {
                try {
                    const resultado = await somar(2, 1);
                    console.log(`A operação foi bem sucedida! O número ${resultado} é par`);
                } catch (error) {
                    console.log(`A operação falhou! ${error.message}`)
                }   
            })();

            async function consomeSomar() {
                try {
                    const resultado = await somar(1, 1);
                    console.log(`A operação foi bem sucedida! O número ${resultado} é par`);
                } catch (error) {
                    console.log(`A operação falhou! ${error.message}`)
                }            
            }

        /*2) Crie uma função dobrarEm5Segundos(numero, ) que dobre o valor de um número após 5 segundos. Se o valor recebido não for um número
        ele irá chamar a cb passando um erro. 

        callback(error, result) => Se um erro for passado irá mostrar a mensagem: "A operação falhou! [mensagem do erro]".
        Senão, irá mostrar a mensagem: "A operação foi bem sucedida! O resultado é [result]".*/


        function dobrarEm5Segundos(numero) {
            return new Promise((resolve, reject) => {
                setTimeout(() => {
                    if (isNaN(numero)) {
                        reject(new TypeError("O valor precisa ser numérico"));
                    } else {
                        const dobro = numero * 2;
                        resolve(dobro);
                    }
                }, 5000);
            });
        }
        /*dobrarEm5Segundos(2)
                .then(resultado => console.log(`A operação foi bem sucedida! O resultado é ${resultado}`))
                .catch(error => console.log(`A operação falhou! ${error.message}`));*/

      

        
           (async () => {
               try {
                   const resultado = await  dobrarEm5Segundos(2)
                   console.log(`A operação foi bem sucedida! O resultado é ${resultado}`)
               }catch (error) {
                console.log(`A operação falhou! ${error.message}`)
               }
           }) ()

           async function dobrarSegundos() {
            try {
                   const resultado = await  dobrarEm5Segundos(2)
                   console.log(`A operação foi bem sucedida! O resultado é ${resultado}`)
               }catch (error) {
                console.log(`A operação falhou! ${error.message}`)
               }
           }
             dobrarSegundos()

             //exercicio 3

             const listaPessoas = [
                {
                    nome: "João",
                    idade: 25,
                    email: "joao@email.com"
                },
                {
                    nome: "Pedro",
                    idade: 33,
                    email: "pedro@email.com"
                },
                {
                    nome: "Marcos",
                    idade: 16,
                    email: "marcos@email.com"
                }
            ];

            class UserNotFoundError extends Error {
                constructor(message) {
                    super(message);
                    this.name = "UserNotFoundError";
                }
            }

            function obtemUsuarioPeloNome(nome) {
                return new Promise((resolve, reject) => {
                    setTimeout(() => {
                        const usuario = listaPessoas.find(pessoa => pessoa.nome === nome);

                        if (!usuario) {
                            reject(new UserNotFoundError("Usuário não está cadastrado"));
                        } else {
                            resolve(usuario);
                        }
                    }, 3000);
                });                        
            }

            obtemUsuarioPeloNome("Pedr")
                .then(usuario => console.log(`Usuário encontrado:\nnome: ${usuario.nome}\nidade: ${usuario.idade}\nemail: ${usuario.email}.`))
                .catch(error => console.log(`Ocorreu um erro! ${error.message}.`));

                (async () => {
                    try {
                    const usuario = await obtemUsuarioPeloNome("Pedr")
                    console.log(`Usuário encontrado:\nnome: ${usuario.nome}\nidade: ${usuario.idade}\nemail: ${usuario.email}.`)
                    
                    } catch{
                        console.log(`Ocorreu um erro! ${error.message}.`)
                    }
                })

    </script>

</body>

</html>